Workbook

Sheet Registo_Diario_Motorista
A1: ID Rota | B1: Data | C1: Tipo Viagem | D1: Tipo Veiculo | E1: Cliente / Local | F1: KM Inicial | G1: KM Final | H1: KM Totais Cliente | I1: KG Carregados | J1: KG Descarregados | K1: Litros Abastecidos | L1: Custo Abastecido (€) | M1: Zona Portagem | N1: Portagens Extra (€) | O1: Noites Fora | P1: Alimentação (€) | Q1: Horas Extra
A2: BOTO | B2: =IF(A2="", "", IF(B2="", TODAY(), B2)) -> 46172 | C2: Ida | D2: CAMIAO+REBOQUE | E2: Agromundo | F2: 345182 | G2: 345880 | H2: =G2-F2 -> 698 | I2: 0 | J2: =2240+2240+5712+2856+2880+720+5760+3808 -> 26216 | K2: 291.11 | L2: 494.6 | M2: VilarFormoso | N2: 15.05 | O2: 70 | P2: 10.5
A3: BOTO | B3: =IF(A3="", "", IF(B3="", TODAY(), B3)) -> 46175 | C3: Volta | D3: CAMIAO+REBOQUE | E3: Tecfil | F3: 345880 | G3: 346584 | H3: =G3-F3 -> 704 | I3: 0 | J3: 0 | K3: 318 | L3: 448.06 | M3: VilarFormoso | N3: 15.05 | P3: 18.85 | Q3: 3
A4: oe | B4: =IF(A4="", "", IF(B4="", TODAY(), B4)) -> 46176 | C4: Ida | D4: CAMIAO | E4: rede | F4: 346584 | G4: 346675 | H4: =G4-F4 -> 91 | I4: 0 | J4: 339 | M4: MarTorres3
A5: oe | B5: =IF(A5="", "", IF(B5="", TODAY(), B5)) -> 46176 | C5: Ida | D5: CAMIAO | E5: sal | F5: 346675 | G5: 346678 | H5: =G5-F5 -> 3 | I5: 112 | J5: 2863 | M5: SPortagem
A6: oe | B6: =IF(A4="""", """", IF(B4="""", TODAY(), B4)) -> 46176 | C6: Ida | D6: CAMIAO | E6: maravedis | F6: 346678 | G6: 346696 | H6: =G6-F6 -> 18 | I6: 0 | J6: 300 | M6: SPortagem
A7: oe | B7: =IF(A7="", "", IF(B7="", TODAY(), B7)) -> 46176 | C7: Ida | D7: CAMIAO | E7: cyr | F7: 346696 | G7: 346705 | H7: =G7-F7 -> 9 | I7: 0 | J7: 2312 | M7: SPortagem
A8: oe | B8: =IF(A8="", "", IF(B8="", TODAY(), B8)) -> 46176 | C8: Ida | D8: CAMIAO | E8: vecotorres | F8: 346705 | G8: 346716 | H8: =G8-F8 -> 11 | I8: 0 | J8: 4832 | M8: SPortagem
A9: oe | B9: =IF(A9="", "", IF(B9="", TODAY(), B9)) -> 46176 | C9: Ida | D9: CAMIAO | E9: liscampo | F9: 346716 | G9: 346750 | H9: =G9-F9 -> 34 | I9: 0 | J9: 800 | M9: SPortagem
A10: oe | B10: =IF(A10="", "", IF(B10="", TODAY(), B10)) -> 46176 | C10: Ida | D10: CAMIAO | E10: morgado | F10: 346750 | G10: 346812 | H10: =G10-F10 -> 62 | I10: 0 | J10: 419 | M10: SPortagem
A11: oe | B11: =IF(A11="", "", IF(B11="", TODAY(), B11)) -> 46176 | C11: Ida | D11: CAMIAO | E11: esequiel | F11: 346812 | G11: 346820 | H11: =G11-F11 -> 8 | I11: 0 | J11: 500 | M11: SPortagem
A12: oe | B12: =IF(A12="", "", IF(B12="", TODAY(), B12)) -> 46176 | C12: Volta | D12: VAZIO | E12: volta | F12: 346820 | G12: 346873 | H12: =G12-F12 -> 53 | I12: 0 | J12: 0 | M12: SPortagem | Q12: 1
B13: =IF(A13="", "", IF(B13="", TODAY(), B13)) | H13: =G13-F13 -> 0 | I13: 0 | J13: 0 | M13: SPortagem
B14: =IF(A14="", "", IF(B14="", TODAY(), B14)) | H14: =G14-F14 -> 0 | M14: Tecges
B15: =IF(A15="", "", IF(B15="", TODAY(), B15)) | H15: =G15-F15 -> 0 | M15: Tecges
B16: =IF(A16="", "", IF(B16="", TODAY(), B16)) | H16: =G16-F16 -> 0 | M16: Tecges
B17: =IF(A17="", "", IF(B17="", TODAY(), B17)) | H17: =G17-F17 -> 0 | M17: Tecges
B18: =IF(A18="", "", IF(B18="", TODAY(), B18)) | H18: =G18-F18 -> 0 | M18: Tecges
B19: =IF(A19="", "", IF(B19="", TODAY(), B19)) | H19: =G19-F19 -> 0 | M19: Tecges
B20: =IF(A20="", "", IF(B20="", TODAY(), B20)) | H20: =G20-F20 -> 0 | M20: Tecges
B21: =IF(A21="", "", IF(B21="", TODAY(), B21)) | H21: =G21-F21 -> 0 | M21: Tecges
B22: =IF(A22="", "", IF(B22="", TODAY(), B22)) | M22: VilarFormoso
B23: =IF(A23="", "", IF(B23="", TODAY(), B23)) | M23: VilarFormoso
B24: =IF(A24="", "", IF(B24="", TODAY(), B24)) | M24: VilarFormoso
B25: =IF(A25="", "", IF(B25="", TODAY(), B25)) | M25: VilarFormoso
B26: =IF(A26="", "", IF(B26="", TODAY(), B26)) | M26: VilarFormoso
B27: =IF(A27="", "", IF(B27="", TODAY(), B27)) | M27: VilarFormoso
B28: =IF(A28="", "", IF(B28="", TODAY(), B28)) | M28: VilarFormoso
B29: =IF(A29="", "", IF(B29="", TODAY(), B29)) | M29: VilarFormoso
B30: =IF(A30="", "", IF(B30="", TODAY(), B30)) | M30: VilarFormoso
B31: =IF(A31="", "", IF(B31="", TODAY(), B31)) | M31: VilarFormoso
B32: =IF(A32="", "", IF(B32="", TODAY(), B32)) | M32: VilarFormoso
B33: =IF(A33="", "", IF(B33="", TODAY(), B33)) | M33: VilarFormoso
... B48: =IF(A48="", "", IF(B48="", TODAY(), B48)) | M48: VilarFormoso
M49: VilarFormoso
M50: VilarFormoso
M51: VilarFormoso
M52: VilarFormoso
M53: VilarFormoso
M54: VilarFormoso
...

Sheet Viagens_APP
D1: Abril/ Maio
A3: ID Rota | B3: Dias da semana | C3: IDA/VOLTA | D3: Cliente | E3: KM IN | F3: KM FIM | G3: Km feitos | H3: Zona Portagem | I3: Portagens | J3: Portagens adi | K3: Tipo viagem | L3: Peso Transportado | M3: Coeficiente% | N3: Tonelada-KM | O3: Ton Km Rota | P3: Coef Real | Q3: MediaL | S3: Preço ref combustivel | T3: Total comb Euro | U3: Adblue | V3: Preço Adblue | W3: Custo Motorista | X3: Custo Veiculo | Y3: Noites | Z3: Alimentação | AA3: Horas a mais | AB3: Preço total H | AC3: Custo | AD3: Preço KG | AE3: Custo atribuído ao cliente | AF3: Custo total da rota | AG3: Preço minimo | AH3: Receita total da rota | AI3: Lucro da rota | AJ3: Receita Paga pelo cliente | AK3: Alerta Automatico | AL3: LitrosESPAHA | AM3: CombsESPAHA
A4: HILP01 | B4: 29 | C4: Ida | D4: Hilplas Tecfil | G4: 580 | H4: =IFERROR(VLOOKUP(A4, Registo_Diario_Motorista!$A$2:$M$5001, 13, FALSE), "") | I4: =IFERROR(VLOOKUP(H4, Tabela_ConsPort!$D$2:$E$9, 2, FALSE), 0) -> 0 | K4: CAMIAO+REBOQUE | L4: 28000 | M4: =IF(K4="LEVE","Volume",L4/IF(K4="CAMIAO+REBOQUE",24000,14000)) -> 1.1666667 | N4: =L4*G4 -> 16240000 | O4: =SUMIF(A:A,A4,N:N) -> 16240000 | P4: =IF(OR(L4=0, I4="VAZIO", I4="RETORNO"), 1, If(I4="CAMIAO", IF(L4/14000 >= 1, 1, L4/14000), IF(L4/24000 >= 1, 1, L4/24000))) -> 1 | Q4: =VLOOKUP(L4, Tabela_ConsPort!$A$2:$B$7, 2, TRUE) -> 45 | R4: =Q4/100*G4 -> 261 | S4: 1.834 | T4: =R4*S4 -> 478.674 | U4: =(G4*2.5)/100 -> 14.5 | V4: =U4*0.3 -> 4.35 | W4: =custo_motorista_e_veiculo!C$11*G4 -> 154.93601 | X4: =G4*custo_motorista_e_veiculo!L$13 -> 159.27851 | Y4: 70 | Z4: 10 | AA4: 0 | AB4: =AA4*8 -> 0 | AC4: =J4+T4+W4+X4+V4 -> 797.23853 | AD4: =IFERROR(AC4/L4, 0) -> 0.028472804 | AE4: =P4*SUMIF(A:A,A4,AF:AF) -> 1487.7331 | AF4: =SUMIFS(AC:AC,A:A,A4)+SUMIFS(Y:Y,A:A,A4)+SUMIFS(Z:Z,A:A,A4)+SUMIFS(AB:AB,A:A,A4)+SUMIFS(I:I,A:A,A4) -> 1487.7331 | AG4: =SUMIFS(AC:AC, A:A, A4) * 1.25 -> 1727.1663 | AH4: =SUMIFS(AJ:AJ,A:A,A4) -> 1700 | AI4: =SUMIF(A:A, A4, AH:AH) - SUMIF(A:A, A4, AF:AF) -> 212.26695 | AJ4: 1700 | AK4: =IF(AI4<0, "🔴 PREJUÍZO", "🟢 OK") -> 🟢 OK
A5: HILP01 | B5: 30 | C5: Volta | D5: Vazio | G5: 580 | H5: =IFERROR(VLOOKUP(A5, Registo_Diario_Motorista!$A$2:$M$5001, 13, FALSE), "") | I5: =IFERROR(VLOOKUP(H5, Tabela_ConsPort!$D$2:$E$9, 2, FALSE), 0) -> 0 | K5: RETORNO | L5: 0 | M5: =IF(K5="LEVE","Volume",L5/IF(K5="CAMIAO+REBOQUE",24000,14000)) -> 0 | N5: =L5*G5 -> 0 | O5: =SUMIF(A:A,A5,N:N) -> 16240000 | P5: =IF(OR(L5=0, I5="VAZIO", I5="RETORNO"), 1, If(I5="CAMIAO", IF(L5/14000 >= 1, 1, L5/14000), IF(L5/24000 >= 1, 1, L5/24000))) -> 1 | Q5: =VLOOKUP(L5, Tabela_ConsPort!$A$2:$B$7, 2, TRUE) -> 25 | R5: =Q5/100*G5 -> 145 | S5: 1.834 | T5: =R5*S5 -> 265.93 | U5: =(G5*2.5)/100 -> 14.5 | V5: =U5*0.3 -> 4.35 | W5: =custo_motorista_e_veiculo!C$11*G5 -> 154.93601 | X5: =G5*custo_motorista_e_veiculo!L$13 -> 159.27851 | Y5: 0 | Z5: 18 | AA5: 1 | AB5: =AA5*8 -> 8 | AC5: =J5+T5+W5+X5+V5 -> 584.49453 | AD5: =IFERROR(AC5/L5, 0) -> 0
H6: =IFERROR(VLOOKUP(A6, Registo_Diario_Motorista!$A$2:$M$5001, 13, FALSE), "") | M6: =IF(K6="LEVE","Volume",L6/IF(K6="CAMIAO+REBOQUE",24000,14000)) -> 0
A7: GA1 | B7: 46178 | C7: Ida | D7: A2 | E7: 338165 | F7: 338318 | G7: =F7-E7 -> 153 | H7: =IFERROR(VLOOKUP(A7, Registo_Diario_Motorista!$A$2:$M$5001, 13, FALSE), "") | I7: =IFERROR(VLOOKUP(H7, Tabela_ConsPort!$D$2:$E$9, 2, FALSE), 0) -> 0 | K7: CAMIAO+REBOQUE | L7: =20000-L8-L9-L10-L11 -> 11520 | M7: =IF(K7="LEVE","Volume",L7/IF(K7="CAMIAO+REBOQUE",24000,14000)) -> 0.48 | N7: =L7*G7 -> 1762560 | O7: =SUMIF(A:A,A7,N:N) -> 2171440 | P7: =IF(OR(L7=0, I7="VAZIO", I7="RETORNO"), 1, If(I7="CAMIAO", IF(L7/14000 >= 1, 1, L7/14000), IF(L7/24000 >= 1, 1, L7/24000))) -> 0.48 | Q7: =VLOOKUP(L7, Tabela_ConsPort!$A$2:$B$7, 2, TRUE) -> 28 | R7: =Q7/100*G7 -> 42.84 | S7: 1.834 | T7: =R7*S7 -> 78.56856 | U7: =(G7*2.5)/100 -> 3.825 | V7: =U7*0.3 -> 1.1475 | W7: =custo_motorista_e_veiculo!C$11*G7 -> 40.871051 | X7: =G7*custo_motorista_e_veiculo!L$13 -> 42.016574 | Y7: 70 | Z7: 35 | AB7: =AA7*8 -> 0 | AC7: =J7+T7+W7+X7+V7 -> 162.60368 | AD7: =IFERROR(AC7/L7, 0) -> 0.014114903 | AE7: =P7*SUMIF(A:A,A7,AF:AF) -> 274.53309 | AF7: =SUMIFS(AC:AC,A:A,A7)+SUMIFS(Y:Y,A:A,A7)+SUMIFS(Z:Z,A:A,A7)+SUMIFS(AB:AB,A:A,A7)+SUMIFS(I:I,A:A,A7) -> 571.94394 | AG7: =SUMIFS(AC:AC, A:A, A7) * 1.25 -> 583.67992 | AH7: =SUMIFS(AJ:AJ,A:A,A7) -> 1500 | AI7: =SUMIF(A:A, A7, AH:AH) - SUMIF(A:A, A7, AF:AF) -> 928.05606 | AJ7: 1500 | AK7: =IF(AI7<0, "🔴 PREJUÍZO", "🟢 OK") -> 🟢 OK
A8: GA1 | B8: 46179 | C8: Ida | D8: tecfence | E8: 338318 | F8: 338358 | G8: =F8-E8 -> 40 | H8: =IFERROR(VLOOKUP(A8, Registo_Diario_Motorista!$A$2:$M$5001, 13, FALSE), "") | I8: =IFERROR(VLOOKUP(H8, Tabela_ConsPort!$D$2:$E$9, 2, FALSE), 0) -> 0 | K8: CAMIAO | L8: 5620 | M8: =IF(K8="LEVE","Volume",L8/IF(K8="CAMIAO+REBOQUE",24000,14000)) -> 0.40142857 | N8: =L8*G8 -> 224800 | O8: =SUMIF(A:A,A8,N:N) -> 2171440 | P8: =IF(OR(L8=0, I8="VAZIO", I8="RETORNO"), 1, If(I8="CAMIAO", IF(L8/14000 >= 1, 1, L8/14000), IF(L8/24000 >= 1, 1, L8/24000))) -> 0.23416667 | Q8: =VLOOKUP(L8, Tabela_ConsPort!$A$2:$B$7, 2, TRUE) -> 25 | R8: =Q8/100*G8 -> 10 | S8: 1.834 | T8: =R8*S8 -> 18.34 | U8: =(G8*2.5)/100 -> 1 | V8: =U8*0.3 -> 0.3 | W8: =custo_motorista_e_veiculo!C$11*G8 -> 10.685242 | X8: =G8*custo_motorista_e_veiculo!L$13 -> 10.984725 | AB8: =AA8*8 -> 0 | AC8: =J8+T8+W8+X8+V8 -> 40.309967 | AD8: =IFERROR(AC8/L8, 0) -> 0.007172592 | AE8: =P8*SUMIF(A:A,A8,AF:AF) -> 133.93021
A9: GA1 | B9: 46180 | C9: Ida | D9: santymar | E9: 338358 | F9: 338519 | G9: =F9-E9 -> 161 | H9: =IFERROR(VLOOKUP(A9, Registo_Diario_Motorista!$A$2:$M$5001, 13, FALSE), "") | I9: =IFERROR(VLOOKUP(H9, Tabela_ConsPort!$D$2:$E$9, 2, FALSE), 0) -> 0 | K9: CAMIAO | L9: 200 | M9: =IF(K9="LEVE","Volume",L9/IF(K9="CAMIAO+REBOQUE",24000,14000)) -> 0.014285714 | N9: =L9*G9 -> 32200 | O9: =SUMIF(A:A,A9,N:N) -> 2171440 | P9: =IF(OR(L9=0, I9="VAZIO", I9="RETORNO"), 1, If(I9="CAMIAO", IF(L9/14000 >= 1, 1, L9/14000), IF(L9/24000 >= 1, 1, L9/24000))) -> 0.0083333333 | Q9: =VLOOKUP(L9, Tabela_ConsPort!$A$2:$B$7, 2, TRUE) -> 25 | R9: =Q9/100*G9 -> 40.25 | S9: 1.834 | T9: =R9*S9 -> 73.8185 | U9: =(G9*2.5)/100 -> 4.025 | V9: =U9*0.3 -> 1.2075 | W9: =custo_motorista_e_veiculo!C$11*G9 -> 43.008099 | X9: =G9*custo_motorista_e_veiculo!L$13 -> 44.213519 | AB9: =AA9*8 -> 0 | AC9: =J9+T9+W9+X9+V9 -> 162.24762 | AD9: =IFERROR(AC9/L9, 0) -> 0.81123809 | AE9: =P9*SUMIF(A:A,A9,AF:AF) -> 4.7661995
A10: GA1 | B10: 46181 | C10: Ida | D10: chamorro | E10: 338519 | F10: 338537 | G10: =F10-E10 -> 18 | H10: =IFERROR(VLOOKUP(A10, Registo_Diario_Motorista!$A$2:$M$5001, 13, FALSE), "") | I10: =IFERROR(VLOOKUP(H10, Tabela_ConsPort!$D$2:$E$9, 2, FALSE), 0) -> 0 | K10: CAMIAO | L10: 1060 | M10: =IF(K10="LEVE","Volume",L10/IF(K10="CAMIAO+REBOQUE",24000,14000)) -> 0.075714286 | N10: =L10*G10 -> 19080 | O10: =SUMIF(A:A,A10,N:N) -> 2171440 | P10: =IF(OR(L10=0, I10="VAZIO", I10="RETORNO"), 1, If(I10="CAMIAO", IF(L10/14000 >= 1, 1, L10/14000), IF(L10/24000 >= 1, 1, L10/24000))) -> 0.044166667 | Q10: =VLOOKUP(L10, Tabela_ConsPort!$A$2:$B$7, 2, TRUE) -> 25 | R10: =Q10/100*G10 -> 4.5 | S10: 1.834 | T10: =R10*S10 -> 8.253 | U10: =(G10*2.5)/100 -> 0.45 | V10: =U10*0.3 -> 0.135 | W10: =custo_motorista_e_veiculo!C$11*G10 -> 4.8083589 | X10: =G10*custo_motorista_e_veiculo!L$13 -> 4.9431263 | AB10: =AA10*8 -> 0 | AC10: =J10+T10+W10+X10+V10 -> 18.139485 | AD10: =IFERROR(AC10/L10, 0) -> 0.017112722 | AE10: =P10*SUMIF(A:A,A10,AF:AF) -> 25.260857
A11: GA1 | B11: 46182 | C11: Ida | D11: melgaco | E11: 338537 | F11: 338620 | G11: =F11-E11 -> 83 | H11: =IFERROR(VLOOKUP(A11, Registo_Diario_Motorista!$A$2:$M$5001, 13, FALSE), "") | I11: =IFERROR(VLOOKUP(H11, Tabela_ConsPort!$D$2:$E$9, 2, FALSE), 0) -> 0 | K11: CAMIAO | L11: 1600 | M11: =IF(K11="LEVE","Volume",L11/IF(K11="CAMIAO+REBOQUE",24000,14000)) -> 0.11428571 | N11: =L11*G11 -> 132800 | O11: =SUMIF(A:A,A11,N:N) -> 2171440 | P11: =IF(OR(L11=0, I11="VAZIO", I11="RETORNO"), 1, If(I11="CAMIAO", IF(L11/14000 >= 1, 1, L11/14000), IF(L11/24000 >= 1, 1, L11/24000))) -> 0.066666667 | Q11: =VLOOKUP(L11, Tabela_ConsPort!$A$2:$B$7, 2, TRUE) -> 25 | R11: =Q11/100*G11 -> 20.75 | S11: 1.834 | T11: =R11*S11 -> 38.0555 | U11: =(G11*2.5)/100 -> 2.075 | V11: =U11*0.3 -> 0.6225 | W11: =custo_motorista_e_veiculo!C$11*G11 -> 22.171877 | X11: =G11*custo_motorista_e_veiculo!L$13 -> 22.793305 | AB11: =AA11*8 -> 0 | AC11: =J11+T11+W11+X11+V11 -> 83.643182 | AD11: =IFERROR(AC11/L11, 0) -> 0.052276989 | AE11: =P11*SUMIF(A:A,A11,AF:AF) -> 38.129596
A12: GT1 | B12: 46182 | C12: Volta | D12: Tecfil | E12: 338620 | F12: 338944 | G12: =F12-E12 -> 324 | H12: =IFERROR(VLOOKUP(A12, Registo_Diario_Motorista!$A$2:$M$5001, 13, FALSE), "") | I12: =IFERROR(VLOOKUP(H12, Tabela_ConsPort!$D$2:$E$9, 2, FALSE), 0) -> 0 | K12: CAMIAO+REBOQUE | L12: 3500 | M12: =IF(K12="LEVE","Volume",L12/IF(K12="CAMIAO+REBOQUE",24000,14000)) -> 0.14583333 | N12: =L12*G12 -> 1134000 | O12: =SUMIF(A:A,A12,N:N) -> 1134000 | P12: =IF(OR(L12=0, I12="VAZIO", I12="RETORNO"), 1, If(I12="CAMIAO", IF(L12/14000 >= 1, 1, L12/14000), IF(L12/24000 >= 1, 1, L12/24000))) -> 0.14583333 | Q12: =VLOOKUP(L12, Tabela_ConsPort!$A$2:$B$7, 2, TRUE) -> 25 | R12: =Q12/100*G12 -> 81 | S12: 1.834 | T12: =R12*S12 -> 148.554 | U12: =(G12*2.5)/100 -> 8.1 | V12: =U12*0.3 -> 2.43 | W12: =custo_motorista_e_veiculo!C$11*G12 -> 86.550461 | X12: =G12*custo_motorista_e_veiculo!L$13 -> 88.976274 | AB12: =AA12*8 -> 0 | AC12: =J12+T12+W12+X12+V12 -> 326.51073 | AD12: =IFERROR(AC12/L12, 0) -> 0.093288781 | AE12: =P12*SUMIF(A:A,A12,AF:AF) -> 47.616149 | AF12: =SUMIFS(AC:AC,A:A,A12)+SUMIFS(Y:Y,A:A,A12)+SUMIFS(Z:Z,A:A,A12)+SUMIFS(AB:AB,A:A,A12)+SUMIFS(I:I,A:A,A12) -> 326.51073
H13: =IFERROR(VLOOKUP(A13, Registo_Diario_Motorista!$A$2:$M$5001, 13, FALSE), "")
A14: GA2 | B14: 18/05 | C14: Ida | D14: acuicolas | E14: 341033 | F14: 341349 | G14: =F14-E14 -> 316 | H14: =IFERROR(VLOOKUP(A14, Registo_Diario_Motorista!$A$2:$M$5001, 13, FALSE), "") | I14: =IFERROR(VLOOKUP(H14, Tabela_ConsPort!$D$2:$E$9, 2, FALSE), 0) -> 0 | K14: CAMIAO | L14: 720 | M14: =IF(K14="LEVE","Volume",L14/IF(K14="CAMIAO+REBOQUE",24000,14000)) -> 0.051428571 | N14: =L14*G14 -> 227520 | O14: =SUMIF(A:A,A14,N:N) -> 1308402 | P14: =IF(OR(L14=0, I14="VAZIO", I14="RETORNO"), 1, If(I14="CAMIAO", IF(L14/14000 >= 1, 1, L14/14000), IF(L14/24000 >= 1, 1, L14/24000))) -> 0.03 | Q14: =VLOOKUP(L14, Tabela_ConsPort!$A$2:$B$7, 2, TRUE) -> 25 | R14: =Q14/100*G14 -> 79 | S14: 1.834 | T14: =R14*S14 -> 144.886 | U14: =(G14*2.5)/100 -> 7.9 | V14: =U14*0.3 -> 2.37 | W14: =custo_motorista_e_veiculo!C$11*G14 -> 84.413413 | X14: =G14*custo_motorista_e_veiculo!L$13 -> 86.779329 | Y14: 70 | AB14: =AA14*8 -> 0 | AC14: =J14+T14+W14+X14+V14 -> 318.44874 | AD14: =IFERROR(AC14/L14, 0) -> 0.44228992 | AE14: =P14*SUMIF(A:A,A14,AF:AF) -> 14.809887 | AF14: =SUMIFS(AC:AC,A:A,A14)+SUMIFS(Y:Y,A:A,A14)+SUMIFS(Z:Z,A:A,A14)+SUMIFS(AB:AB,A:A,A14)+SUMIFS(I:I,A:A,A14) -> 493.66289 | AG14: =SUMIFS(AC:AC, A:A, A14) * 1.25 -> 529.57861 | AH14: =SUMIFS(AJ:AJ,A:A,A14) -> 700 | AI14: =SUMIF(A:A, A14, AH:AH) - SUMIF(A:A, A14, AF:AF) -> 906.33711 | AJ14: 700 | AK14: =IF(AI14<0, "🔴 PREJUÍZO", "🟢 OK") -> 🟢 OK
A15: GA2 | B15: 18/05 | C15: Ida | D15: poutada | E15: 341349 | F15: 341448 | G15: =F15-E15 -> 99 | H15: =IFERROR(VLOOKUP(A15, Registo_Diario_Motorista!$A$2:$M$5001, 13, FALSE), "") | I15: =IFERROR(VLOOKUP(H15, Tabela_ConsPort!$D$2:$E$9, 2, FALSE), 0) -> 0 | K15: CAMIAO | L15: 10918 | M15: =IF(K15="LEVE","Volume",L15/IF(K15="CAMIAO+REBOQUE",24000,14000)) -> 0.77985714 | N15: =L15*G15 -> 1080882 | O15: =SUMIF(A:A,A15,N:N) -> 1308402 | P15: =IF(OR(L15=0, I15="VAZIO", I15="RETORNO"), 1, If(I15="CAMIAO", IF(L15/14000 >= 1, 1, L15/14000), IF(L15/24000 >= 1, 1, L15/24000))) -> 0.45491667 | Q15: =VLOOKUP(L15, Tabela_ConsPort!$A$2:$B$7, 2, TRUE) -> 28 | R15: =Q15/100*G15 -> 27.72 | S15: 1.834 | T15: =R15*S15 -> 50.83848 | U15: =(G15*2.5)/100 -> 2.475 | V15: =U15*0.3 -> 0.7425 | W15: =custo_motorista_e_veiculo!C$11*G15 -> 26.445974 | X15: =G15*custo_motorista_e_veiculo!L$13 -> 27.187195 | AB15: =AA15*8 -> 0 | AC15: =J15+T15+W15+X15+V15 -> 105.21415 | AD15: =IFERROR(AC15/L15, 0) -> 0.0096367603 | AE15: =P15*SUMIF(A:A,A15,AF:AF) -> 224.57548 | AH15: =SUMIFS(AJ:AJ,A:A,A15) -> 700 | AI15: =SUMIF(A:A, A15, AH:AH) - SUMIF(A:A, A15, AF:AF) -> 906.33711
A16: RGA2 | B16: 18/05 | C16: Volta | D16: coregal | E16: 341448 | F16: 341466 | G16: =F16-E16 -> 18 | H16: =IFERROR(VLOOKUP(A16, Registo_Diario_Motorista!$A$2:$M$5001, 13, FALSE), "") | I16: =IFERROR(VLOOKUP(H16, Tabela_ConsPort!$D$2:$E$9, 2, FALSE), 0) -> 0 | K16: RETORNO | L16: 0 | M16: =IF(K16="LEVE","Volume",L16/IF(K16="CAMIAO+REBOQUE",24000,14000)) -> 0 | N16: =L16*G16 -> 0 | O16: =SUMIF(A:A,A16,N:N) -> 9900240 | P16: =IF(OR(L16=0, I16="VAZIO", I16="RETORNO"), 1, If(I16="CAMIAO", IF(L16/14000 >= 1, 1, L16/14000), IF(L16/24000 >= 1, 1, L16/24000))) -> 1 | Q16: =VLOOKUP(L16, Tabela_ConsPort!$A$2:$B$7, 2, TRUE) -> 25 | R16: =Q16/100*G16 -> 4.5 | S16: 1.834 | T16: =R16*S16 -> 8.253 | U16: =(G16*2.5)/100 -> 0.45 | V16: =U16*0.3 -> 0.135 | W16: =custo_motorista_e_veiculo!C$11*G16 -> 4.8083589 | X16: =G16*custo_motorista_e_veiculo!L$13 -> 4.9431263 | AB16: =AA16*8 -> 0 | AC16: =J16+T16+W16+X16+V16 -> 18.139485 | AD16: =IFERROR(AC16/L17, 0) -> 0.00078052863 | AE16: =P16*SUMIF(A:A,A16,AF:AF) -> 537.56904 | AF16: =SUMIFS(AC:AC,A:A,A16)+SUMIFS(Y:Y,A:A,A16)+SUMIFS(Z:Z,A:A,A16)+SUMIFS(AB:AB,A:A,A16)+SUMIFS(I:I,A:A,A16) -> 537.56904 | AG16: =SUMIFS(AC:AC, A:A, A16) * 1.25 -> 656.9613 | AH16: =SUMIFS(AJ:AJ,A:A,A16) -> 700 | AI16: =SUMIF(A:A, A16, AH:AH) - SUMIF(A:A, A16, AF:AF) -> 862.43096 | AJ16: 700 | AK16: =IF(AI16<0, "🔴 PREJUÍZO", "🟢 OK") -> 🟢 OK
A17: RGA2 | B17: 18/05 | C17: Volta | D17: Tecfil | E17: 341466 | F17: 341892 | G17: =F17-E17 -> 426 | H17: =IFERROR(VLOOKUP(A17, Registo_Diario_Motorista!$A$2:$M$5001, 13, FALSE), "") | I17: =IFERROR(VLOOKUP(H17, Tabela_ConsPort!$D$2:$E$9, 2, FALSE), 0) -> 0 | K17: CAMIAO+REBOQUE | L17: 23240 | M17: =IF(K17="LEVE","Volume",L17/IF(K17="CAMIAO+REBOQUE",24000,14000)) -> 0.96833333 | N17: =L17*G17 -> 9900240 | O17: =SUMIF(A:A,A17,N:N) -> 9900240 | P17: =IF(OR(L17=0, I17="VAZIO", I17="RETORNO"), 1, If(I17="CAMIAO", IF(L17/14000 >= 1, 1, L17/14000), IF(L17/24000 >= 1, 1, L17/24000))) -> 0.96833333 | Q17: =VLOOKUP(L17, Tabela_ConsPort!$A$2:$B$7, 2, TRUE) -> 35 | R17: =Q17/100*G17 -> 149.1 | S17: 1.834 | T17: =R17*S17 -> 273.4494 | U17: =(G17*2.5)/100 -> 10.65 | V17: =U17*0.3 -> 3.195 | W17: =custo_motorista_e_veiculo!C$11*G17 -> 113.79783 | X17: =G17*custo_motorista_e_veiculo!L$13 -> 116.98732 | AA17: 1.5 | AB17: =AA17*8 -> 12 | AC17: =J17+T17+W17+X17+V17 -> 507.42955 | AD17: =IFERROR(AC17/L18, 0) -> 0 | AE17: =P17*SUMIF(A:A,A17,AF:AF) -> 520.54602 | AH17: =SUMIFS(AJ:AJ,A:A,A17) -> 700 | AI17: =SUMIF(A:A, A17, AH:AH) - SUMIF(A:A, A17, AF:AF) -> 862.43096
H18: =IFERROR(VLOOKUP(A18, Registo_Diario_Motorista!$A$2:$M$5001, 13, FALSE), "") | I18: =IFERROR(VLOOKUP(H18, Tabela_ConsPort!$D$2:$E$9, 2, FALSE), 0) -> 0 | M18: =IF(K18="LEVE","Volume",L18/IF(K18="CAMIAO+REBOQUE",24000,14000)) -> 0 | AC18: =J18+T18+W18+X18+V18 -> 0 | AF18: =SUMIFS(AC:AC,A:A,A18)+SUMIFS(Y:Y,A:A,A18)+SUMIFS(Z:Z,A:A,A18)+SUMIFS(AB:AB,A:A,A18)+SUMIFS(I:I,A:A,A18) -> 0 | AH18: =SUMIFS(AJ:AJ,A:A,A18) -> 0
A19: za1 | B19: 20/05 | C19: Ida | D19: fertimaq | E19: 341892 | F19: 342337 | G19: =F19-E19 -> 445 | H19: =IFERROR(VLOOKUP(A19, Registo_Diario_Motorista!$A$2:$M$5001, 13, FALSE), "") | I19: =IFERROR(VLOOKUP(H19, Tabela_ConsPort!$D$2:$E$9, 2, FALSE), 0) -> 0 | K19: CAMIAO+REBOQUE | L19: =1120*14 -> 15680 | M19: =IF(K19="LEVE","Volume",L19/IF(K19="CAMIAO+REBOQUE",24000,14000)) -> 0.65333333 | N19: =L19*G19 -> 6977600 | O19: =SUMIF(A:A,A19,N:N) -> 9947840 | P19: =IF(OR(L19=0, I19="VAZIO", I19="RETORNO"), 1, If(I19="CAMIAO", IF(L19/14000 >= 1, 1, L19/14000), IF(L19/24000 >= 1, 1, L19/24000))) -> 0.65333333 | Q19: =VLOOKUP(L19, Tabela_ConsPort!$A$2:$B$7, 2, TRUE) -> 31 | R19: =Q19/100*G19 -> 137.95 | S19: 1.834 | T19: =R19*S19 -> 253.0003 | U19: =(G19*2.5)/100 -> 11.125 | V19: =U19*0.3 -> 3.3375 | W19: =custo_motorista_e_veiculo!C$11*G19 -> 118.87332 | X19: =G19*custo_motorista_e_veiculo!L$13 -> 122.20507 | Y19: 70 | Z19: 17 | AB19: =AA19*8 -> 0 | AC19: =J19+T19+W19+X19+V19 -> 497.41619 | AD19: =IFERROR(AC19/L19, 0) -> 0.031722971 | AE19: =P19*SUMIF(A:A,A19,AF:AF) -> 535.26827 | AF19: =SUMIFS(AC:AC,A:A,A19)+SUMIFS(Y:Y,A:A,A19)+SUMIFS(Z:Z,A:A,A19)+SUMIFS(AB:AB,A:A,A19)+SUMIFS(I:I,A:A,A19) -> 819.28817 | AG19: =SUMIFS(AC:AC, A:A, A19) * 1.25 -> 915.36022 | AH19: =SUMIFS(AJ:AJ,A:A,A19) -> 785 | AI19: =SUMIF(A:A, A19, AH:AH) - SUMIF(A:A, A19, AF:AF) -> 750.71183 | AJ19: 785 | AK19: =IF(AI19<0, "🔴 PREJUÍZO", "🟢 OK") -> 🟢 OK
A20: za1 | B20: 20/05 | C20: Ida | D20: tecnipec | E20: 342337 | F20: 342558 | G20: =F20-E20 -> 221 | H20: =IFERROR(VLOOKUP(A20, Registo_Diario_Motorista!$A$2:$M$5001, 13, FALSE), "") | I20: =IFERROR(VLOOKUP(H20, Tabela_ConsPort!$D$2:$E$9, 2, FALSE), 0) -> 0 | K20: CAMIAO | L20: =1120*12 -> 13440 | M20: =IF(K20="LEVE","Volume",L20/IF(K20="CAMIAO+REBOQUE",24000,14000)) -> 0.96 | N20: =L20*G20 -> 2970240 | O20: =SUMIF(A:A,A20,N:N) -> 9947840 | P20: =IF(OR(L20=0, I20="VAZIO", I20="RETORNO"), 1, If(I20="CAMIAO", IF(L20/14000 >= 1, 1, L20/14000), IF(L20/24000 >= 1, 1, L20/24000))) -> 0.56 | Q20: =VLOOKUP(L20, Tabela_ConsPort!$A$2:$B$7, 2, TRUE) -> 28 | R20: =Q20/100*G20 -> 61.88 | S20: 1.834 | T20: =R20*S20 -> 113.48792 | U20: =(G20*2.5)/100 -> 5.525 | V20: =U20*0.3 -> 1.6575 | W20: =custo_motorista_e_veiculo!C$11*G20 -> 59.035963 | X20: =G20*custo_motorista_e_veiculo!L$13 -> 60.690606 | AB20: =AA20*8 -> 0 | AC20: =J20+T20+W20+X20+V20 -> 234.87199 | AD20: =IFERROR(AC20/L20, 0) -> 0.017475594 | AE20: =P20*SUMIF(A:A,A20,AF:AF) -> 458.80138 | AH20: =SUMIFS(AJ:AJ,A:A,A20) -> 785
A21: za2 | B21: 21 | C21: Volta | D21: Recolha | E21: 342558 | F21: 342713 | G21: =F21-E21 -> 155 | H21: =IFERROR(VLOOKUP(A21, Registo_Diario_Motorista!$A$2:$M$5001, 13, FALSE), "") | I21: =IFERROR(VLOOKUP(H21, Tabela_ConsPort!$D$2:$E$9, 2, FALSE), 0) -> 0 | K21: RETORNO | L21: 0 | M21: =IF(K21="LEVE","Volume",L21/IF(K21="CAMIAO+REBOQUE",24000,14000)) -> 0 | N21: =L21*G21 -> 0 | O21: =SUMIF(A:A,A21,N:N) -> 4052340 | P21: =IF(OR(L21=0, I21="VAZIO", I21="RETORNO"), 1, If(I21="CAMIAO", IF(L21/14000 >= 1, 1, L21/14000), IF(L21/24000 >= 1, 1, L21/24000))) -> 1 | Q21: =VLOOKUP(L21, Tabela_ConsPort!$A$2:$B$7, 2, TRUE) -> 25 | R21: =Q21/100*G21 -> 38.75 | S21: 1.834 | T21: =R21*S21 -> 71.0675 | U21: =(G21*2.5)/100 -> 3.875 | V21: =U21*0.3 -> 1.1625 | W21: =custo_motorista_e_veiculo!C$11*G21 -> 41.405313 | X21: =G21*custo_motorista_e_veiculo!L$13 -> 42.56581 | Z21: 18.7 | AB21: =AA21*8 -> 0 | AC21: =J21+T21+W21+X21+V21 -> 156.20112 | AD21: =IFERROR(AC21/L21, 0) -> 0 | AE21: =P21*SUMIF(A:A,A21,AF:AF) -> 697.13398 | AF21: =SUMIFS(AC:AC,A:A,A21)+SUMIFS(Y:Y,A:A,A21)+SUMIFS(Z:Z,A:A,A21)+SUMIFS(AB:AB,A:A,A21)+SUMIFS(I:I,A:A,A21) -> 697.13398 | AG21: =SUMIFS(AC:AC, A:A, A21) * 1.25 -> 798.04248 | AH21: =SUMIFS(AJ:AJ,A:A,A21) -> 905 | AI21: =SUMIF(A:A, A21, AH:AH) - SUMIF(A:A, A21, AF:AF) -> 1112.866 | AJ21: 905 | AK21: =IF(AI21<0, "🔴 PREJUÍZO", "🟢 OK") -> 🟢 OK
A22: za2 | B22: 21 | C22: Volta | D22: destino tecfil | E22: 342713 | F22: 343192 | G22: =F22-E22 -> 479 | H22: =IFERROR(VLOOKUP(A22, Registo_Diario_Motorista!$A$2:$M$5001, 13, FALSE), "") | I22: =IFERROR(VLOOKUP(H22, Tabela_ConsPort!$D$2:$E$9, 2, FALSE), 0) -> 0 | K22: CAMIAO+REBOQUE | L22: 8460 | M22: =IF(K22="LEVE","Volume",L22/IF(K22="CAMIAO+REBOQUE",24000,14000)) -> 0.3525 | N22: =L22*G22 -> 4052340 | O22: =SUMIF(A:A,A22,N:N) -> 4052340 | P22: =IF(OR(L22=0, I22="VAZIO", I22="RETORNO"), 1, If(I22="CAMIAO", IF(L22/14000 >= 1, 1, L22/14000), IF(L22/24000 >= 1, 1, L22/24000))) -> 0.3525 | Q22: =VLOOKUP(L22, Tabela_ConsPort!$A$2:$B$7, 2, TRUE) -> 25 | R22: =Q22/100*G22 -> 119.75 | S22: 1.83 | T22: =R22*S22 -> 219.1425 | U22: =(G22*2.5)/100 -> 11.975 | V22: =U22*0.3 -> 3.5925 | W22: =custo_motorista_e_veiculo!C$11*G22 -> 127.95577 | X22: =G22*custo_motorista_e_veiculo!L$13 -> 131.54208 | AA22: 5 | AB22: =AA22*8 -> 40 | AC22: =J22+T22+W22+X22+V22 -> 482.23286 | AD22: =IFERROR(AC22/L22, 0) -> 0.05700152 | AH22: =SUMIFS(AJ:AJ,A:A,A22) -> 905
H23: =IFERROR(VLOOKUP(A23, Registo_Diario_Motorista!$A$2:$M$5001, 13, FALSE), "")
A24: =Registo_Diario_Motorista!A2 -> BOTO | B24: =Registo_Diario_Motorista!B2 -> 46172 | C24: Ida | D24: =Registo_Diario_Motorista!E2 -> Agromundo | E24: =Registo_Diario_Motorista!F2 -> 345182 | F24: =Registo_Diario_Motorista!G2 -> 345880 | G24: =IFERROR(__xludf.DUMMYFUNCTION("IFERROR(FILTER(Registo_Diario_Motorista!H:H, Registo_Diario_Motorista!A:A = A24, Registo_Diario_Motorista!C:C = C24, Registo_Diario_Motorista!E:E = D24), 0)"),698.0) -> 698 | H24: VilarFormoso | I24: =IFERROR(VLOOKUP(H24, Tabela_ConsPort!D:E, 2, FALSE), 0) -> 18.15 | J24: =SUMIFS(Registo_Diario_Motorista!N:N, Registo_Diario_Motorista!A:A, A24, Registo_Diario_Motorista!C:C, C24, Registo_Diario_Motorista!E:E, D24) -> 15.05 | K24: =IFERROR(__xludf.DUMMYFUNCTION("IFERROR(FILTER(Registo_Diario_Motorista!D:D, Registo_Diario_Motorista!A:A = A24, Registo_Diario_Motorista!C:C = C24), """")"),"CAMIAO+REBOQUE") -> CAMIAO+REBOQUE | L24: =SUMIFS(Registo_Diario_Motorista!J:J, Registo_Diario_Motorista!A:A, A24, Registo_Diario_Motorista!C:C, C24, Registo_Diario_Motorista!E:E, D24) -> 26216 | M24: =IF(K24="LEVE","Volume",L24/IF(K24="CAMIAO+REBOQUE",24000,14000)) -> 1.0923333 | N24: =L24*G24 -> 18298768 | O24: =SUMIF(A:A,A24,N:N) -> 18298768 | P24: =IF(OR(L24=0, I24="VAZIO", I24="RETORNO"), 1, If(I24="CAMIAO", IF(L24/14000 >= 1, 1, L24/14000), IF(L24/24000 >= 1, 1, L24/24000))) -> 1 | Q24: =VLOOKUP(L24, Tabela_ConsPort!$A$2:$B$7, 2, TRUE) -> 38 | R24: =Q24/100*G24 -> 265.24 | S24: 1.83 | T24: =R24*S24 -> 485.3892 | U24: =(G24*2.5)/100 -> 17.45 | V24: =U24*0.3 -> 5.235 | W24: =custo_motorista_e_veiculo!C$11*G24 -> 186.45747 | X24: =G24*custo_motorista_e_veiculo!L$13 -> 191.68345 | Y24: =SUMIFS(Registo_Diario_Motorista!O:O, Registo_Diario_Motorista!A:A, A24, Registo_Diario_Motorista!C:C, C24, Registo_Diario_Motorista!E:E, D24) -> 70 | Z24: =SUMIFS(Registo_Diario_Motorista!P:P, Registo_Diario_Motorista!A:A, A24, Registo_Diario_Motorista!C:C, C24, Registo_Diario_Motorista!E:E, D24) -> 10.5 | AA24: =SUMIFS(Registo_Diario_Motorista!Q:Q, Registo_Diario_Motorista!A:A, A24, Registo_Diario_Motorista!C:C, C24, Registo_Diario_Motorista!E:E, D24) -> 0 | AB24: =AA24*8 -> 0 | AC24: =J24+T24+W24+X24+V24 -> 883.81513 | AD24: =IFERROR(AC24/L24, 0) -> 0.033712814 | AE24: =P24*SUMIF(A:A,A24,AF:AF) -> 1767.2666 | AF24: =SUMIFS(AC:AC,A:A,A24)+SUMIFS(Y:Y,A:A,A24)+SUMIFS(Z:Z,A:A,A24)+SUMIFS(AB:AB,A:A,A24)+SUMIFS(I:I,A:A,A24) -> 1767.2666 | AG24: =SUMIFS(AC:AC, A:A, A24) * 1.25 -> 2009.5207 | AH24: =SUMIFS(AJ:AJ,A:A,A24) -> 1799 | AI24: =SUMIF(A:A, A24, AH:AH) - SUMIF(A:A, A24, AF:AF) -> 31.733448 | AJ24: 1799 | AK24: =IF(AI24<0, "🔴 PREJUÍZO", "🟢 OK") -> 🟢 OK | AL24: =IFERROR(__xludf.DUMMYFUNCTION("IFERROR(FILTER(Registo_Diario_Motorista!K:K, Registo_Diario_Motorista!A:A = A24, Registo_Diario_Motorista!C:C = C24), 0)"),291.11) -> 291.11 | AM24: =IFERROR(__xludf.DUMMYFUNCTION("IFERROR(FILTER(Registo_Diario_Motorista!L:L, Registo_Diario_Motorista!A:A = A24, Registo_Diario_Motorista!C:C = C24), 0)"),494.6) -> 494.6
A25: =Registo_Diario_Motorista!A3 -> BOTO | B25: =Registo_Diario_Motorista!B3 -> 46175 | C25: Volta | D25: =Registo_Diario_Motorista!E3 -> Tecfil | E25: =Registo_Diario_Motorista!F3 -> 345880 | F25: =Registo_Diario_Motorista!G3 -> 346584 | G25: =IFERROR(__xludf.DUMMYFUNCTION("IFERROR(FILTER(Registo_Diario_Motorista!H:H, Registo_Diario_Motorista!A:A = A25, Registo_Diario_Motorista!C:C = C25, Registo_Diario_Motorista!E:E = D25), 0)"),704.0) -> 704 | H25: VilarFormoso | I25: =IFERROR(VLOOKUP(H25, Tabela_ConsPort!D:E, 2, FALSE), 0) -> 18.15 | J25: =SUMIFS(Registo_Diario_Motorista!N:N, Registo_Diario_Motorista!A:A, A25, Registo_Diario_Motorista!C:C, C25, Registo_Diario_Motorista!E:E, D25) -> 15.05 | K25: =IFERROR(__xludf.DUMMYFUNCTION("IFERROR(FILTER(Registo_Diario_Motorista!D:D, Registo_Diario_Motorista!A:A = A25, Registo_Diario_Motorista!C:C = C25), """")"),"CAMIAO+REBOQUE") -> CAMIAO+REBOQUE | L25: =SUMIFS(Registo_Diario_Motorista!J:J, Registo_Diario_Motorista!A:A, A25, Registo_Diario_Motorista!C:C, C25, Registo_Diario_Motorista!E:E, D25) -> 0 | M25: =IF(K25="LEVE","Volume",L25/IF(K25="CAMIAO+REBOQUE",24000,14000)) -> 0 | N25: =L25*G25 -> 0 | O25: =SUMIF(A:A,A25,N:N) -> 18298768 | P25: =IF(OR(L25=0, I25="VAZIO", I25="RETORNO"), 1, If(I25="CAMIAO", IF(L25/14000 >= 1, 1, L25/14000), IF(L25/24000 >= 1, 1, L25/24000))) -> 1 | Q25: =VLOOKUP(L25, Tabela_ConsPort!$A$2:$B$7, 2, TRUE) -> 25 | R25: =Q25/100*G25 -> 176 | S25: 1.83 | T25: =R25*S25 -> 322.08 | U25: =(G25*2.5)/100 -> 17.6 | V25: =U25*0.3 -> 5.28 | W25: =custo_motorista_e_veiculo!C$11*G25 -> 188.06026 | X25: =G25*custo_motorista_e_veiculo!L$13 -> 193.33116 | Y25: =SUMIFS(Registo_Diario_Motorista!O:O, Registo_Diario_Motorista!A:A, A25, Registo_Diario_Motorista!C:C, C25, Registo_Diario_Motorista!E:E, D25) -> 0 | Z25: =SUMIFS(Registo_Diario_Motorista!P:P, Registo_Diario_Motorista!A:A, A25, Registo_Diario_Motorista!C:C, C25, Registo_Diario_Motorista!E:E, D25) -> 18.85 | AA25: =SUMIFS(Registo_Diario_Motorista!Q:Q, Registo_Diario_Motorista!A:A, A25, Registo_Diario_Motorista!C:C, C25, Registo_Diario_Motorista!E:E, D25) -> 3 | AB25: =AA25*8 -> 24 | AC25: =J25+T25+W25+X25+V25 -> 723.80142 | AD25: =IFERROR(AC25/L25, 0) -> 0 | AK25: =IF(AI25<0, "🔴 PREJUÍZO", "🟢 OK") -> 🟢 OK | AL25: =IFERROR(__xludf.DUMMYFUNCTION("IFERROR(FILTER(Registo_Diario_Motorista!K:K, Registo_Diario_Motorista!A:A = A25, Registo_Diario_Motorista!C:C = C25), 0)"),318.0) -> 318 | AM25: =IFERROR(__xludf.DUMMYFUNCTION("IFERROR(FILTER(Registo_Diario_Motorista!L:L, Registo_Diario_Motorista!A:A = A25, Registo_Diario_Motorista!C:C = C25), 0)"),448.06) -> 448.06
A26: =Registo_Diario_Motorista!A4 -> oe | B26: =Registo_Diario_Motorista!B4 -> 46176 | C26: Ida | D26: =Registo_Diario_Motorista!E4 -> rede | E26: =Registo_Diario_Motorista!F4 -> 346584 | F26: =Registo_Diario_Motorista!G4 -> 346675 | G26: =IFERROR(__xludf.DUMMYFUNCTION("IFERROR(FILTER(Registo_Diario_Motorista!H:H, Registo_Diario_Motorista!A:A = A26, Registo_Diario_Motorista!C:C = C26, Registo_Diario_Motorista!E:E = D26), 0)"),91.0) -> 91 | H26: MarTorres3 | I26: =IFERROR(VLOOKUP(H26, Tabela_ConsPort!D:E, 2, FALSE), 0) -> 14.15 | J26: =SUMIFS(Registo_Diario_Motorista!N:N, Registo_Diario_Motorista!A:A, A26, Registo_Diario_Motorista!C:C, C26, Registo_Diario_Motorista!E:E, D26) -> 0 | K26: CAMIAO | L26: =SUMIFS(Registo_Diario_Motorista!J:J, Registo_Diario_Motorista!A:A, A26, Registo_Diario_Motorista!C:C, C26, Registo_Diario_Motorista!E:E, D26) -> 339 | M26: =IF(K26="LEVE","Volume",L26/IF(K26="CAMIAO+REBOQUE",24000,14000)) -> 0.024214286 | N26: =L26*G26 -> 30849 | O26: =SUMIF(A:A,A26,N:N) -> 175976 | P26: =IF(OR(L26=0, I26="VAZIO", I26="RETORNO"), 1, If(I26="CAMIAO", IF(L26/14000 >= 1, 1, L26/14000), IF(L26/24000 >= 1, 1, L26/24000))) -> 0.014125 | Q26: =VLOOKUP(L26, Tabela_ConsPort!$A$2:$B$7, 2, TRUE) -> 25 | R26: =Q26/100*G26 -> 22.75 | S26: 1.83 | T26: =R26*S26 -> 41.6325 | U26: =(G26*2.5)/100 -> 2.275 | V26: =U26*0.3 -> 0.6825 | W26: =custo_motorista_e_veiculo!C$11*G26 -> 24.308926 | X26: =G26*custo_motorista_e_veiculo!L$13 -> 24.99025 | Y26: =SUMIFS(Registo_Diario_Motorista!O:O, Registo_Diario_Motorista!A:A, A26, Registo_Diario_Motorista!C:C, C26, Registo_Diario_Motorista!E:E, D26) -> 0 | Z26: =SUMIFS(Registo_Diario_Motorista!P:P, Registo_Diario_Motorista!A:A, A26, Registo_Diario_Motorista!C:C, C26, Registo_Diario_Motorista!E:E, D26) -> 0 | AA26: =SUMIFS(Registo_Diario_Motorista!Q:Q, Registo_Diario_Motorista!A:A, A26, Registo_Diario_Motorista!C:C, C26, Registo_Diario_Motorista!E:E, D26) -> 0 | AB26: =AA26*8 -> 0 | AC26: =J26+T26+W26+X26+V26 -> 91.614176 | AD26: =IFERROR(AC26/L26, 0) -> 0.27024831 | AE26: =P26*SUMIF(A:A,A26,AF:AF) -> 39.802903 | AF26: =SUMIFS(AC:AC,A:A,A26)+SUMIFS(Y:Y,A:A,A26)+SUMIFS(Z:Z,A:A,A26)+SUMIFS(AB:AB,A:A,A26)+SUMIFS(I:I,A:A,A26) -> 313.10051 | AG26: =SUMIFS(AC:AC, A:A, A26) * 1.25 -> 363.68814 | AH26: =SUMIFS(AJ:AJ,A:A,A26) -> 400 | AI26: =SUMIF(A:A, A26, AH:AH) - SUMIF(A:A, A26, AF:AF) -> 782.09538 | AJ26: 400 | AK26: =IF(AI26<0, "🔴 PREJUÍZO", "🟢 OK") -> 🟢 OK | AL26: =IFERROR(__xludf.DUMMYFUNCTION("IFERROR(FILTER(Registo_Diario_Motorista!K:K, Registo_Diario_Motorista!A:A = A26, Registo_Diario_Motorista!C:C = C26), 0)"),"#REF!") -> #REF! | AM26: =IFERROR(__xludf.DUMMYFUNCTION("IFERROR(FILTER(Registo_Diario_Motorista!L:L, Registo_Diario_Motorista!A:A = A26, Registo_Diario_Motorista!C:C = C26), 0)"),"#REF!") -> #REF!
A27: =Registo_Diario_Motorista!A5 -> oe | B27: =Registo_Diario_Motorista!B5 -> 46176 | C27: Ida | D27: =Registo_Diario_Motorista!E5 -> sal | E27: =Registo_Diario_Motorista!F5 -> 346675 | F27: =Registo_Diario_Motorista!G5 -> 346678 | G27: =IFERROR(__xludf.DUMMYFUNCTION("IFERROR(FILTER(Registo_Diario_Motorista!H:H, Registo_Diario_Motorista!A:A = A27, Registo_Diario_Motorista!C:C = C27, Registo_Diario_Motorista!E:E = D27), 0)"),3.0) -> 3 | H27: SPortagem | I27: =IFERROR(VLOOKUP(H27, Tabela_ConsPort!D:E, 2, FALSE), 0) -> 0 | J27: =SUMIFS(Registo_Diario_Motorista!N:N, Registo_Diario_Motorista!A:A, A27, Registo_Diario_Motorista!C:C, C27, Registo_Diario_Motorista!E:E, D27) -> 0 | K27: CAMIAO | L27: =SUMIFS(Registo_Diario_Motorista!J:J, Registo_Diario_Motorista!A:A, A27, Registo_Diario_Motorista!C:C, C27, Registo_Diario_Motorista!E:E, D27) -> 2863 | M27: =IF(K27="LEVE","Volume",L27/IF(K27="CAMIAO+REBOQUE",24000,14000)) -> 0.2045 | N27: =L27*G27 -> 8589 | O27: =SUMIF(A:A,A27,N:N) -> 175976 | P27: =IF(OR(L27=0, I27="VAZIO", I27="RETORNO"), 1, If(I27="CAMIAO", IF(L27/14000 >= 1, 1, L27/14000), IF(L27/24000 >= 1, 1, L27/24000))) -> 0.11929167 | Q27: =VLOOKUP(L27, Tabela_ConsPort!$A$2:$B$7, 2, TRUE) -> 25 | R27: =Q27/100*G27 -> 0.75 | S27: 1.83 | T27: =R27*S27 -> 1.3725 | U27: =(G27*2.5)/100 -> 0.075 | V27: =U27*0.3 -> 0.0225 | W27: =custo_motorista_e_veiculo!C$11*G27 -> 0.80139316 | X27: =G27*custo_motorista_e_veiculo!L$13 -> 0.82385439 | Y27: =SUMIFS(Registo_Diario_Motorista!O:O, Registo_Diario_Motorista!A:A, A27, Registo_Diario_Motorista!C:C, C27, Registo_Diario_Motorista!E:E, D27) -> 0 | Z27: =SUMIFS(Registo_Diario_Motorista!P:P, Registo_Diario_Motorista!A:A, A27, Registo_Diario_Motorista!C:C, C27, Registo_Diario_Motorista!E:E, D27) -> 0 | AA27: =SUMIFS(Registo_Diario_Motorista!Q:Q, Registo_Diario_Motorista!A:A, A27, Registo_Diario_Motorista!C:C, C27, Registo_Diario_Motorista!E:E, D27) -> 0 | AB27: =AA27*8 -> 0 | AC27: =J27+T27+W27+X27+V27 -> 3.0202475 | AD27: =IFERROR(AC27/L27, 0) -> 0.001054924 | AE27: =P27*SUMIF(A:A,A27,AF:AF) -> 336.15254 | AF27: =SUMIFS(AC:AC,A:A,A27)+SUMIFS(Y:Y,A:A,A27)+SUMIFS(Z:Z,A:A,A27)+SUMIFS(AB:AB,A:A,A27)+SUMIFS(I:I,A:A,A27) -> 313.10051 | AG27: =SUMIFS(AC:AC, A:A, A27) * 1.25 -> 363.68814 | AH27: =SUMIFS(AJ:AJ,A:A,A27) -> 400 | AI27: =SUMIF(A:A, A27, AH:AH) - SUMIF(A:A, A27, AF:AF) -> 782.09538 | AK27: =IF(AI27<0, "🔴 PREJUÍZO", "🟢 OK") -> 🟢 OK | AL27: =IFERROR(__xludf.DUMMYFUNCTION("IFERROR(FILTER(Registo_Diario_Motorista!K:K, Registo_Diario_Motorista!A:A = A27, Registo_Diario_Motorista!C:C = C27), 0)"),"#REF!") -> #REF! | AM27: =IFERROR(__xludf.DUMMYFUNCTION("IFERROR(FILTER(Registo_Diario_Motorista!L:L, Registo_Diario_Motorista!A:A = A27, Registo_Diario_Motorista!C:C = C27), 0)"),"#REF!") -> #REF!
A28: =Registo_Diario_Motorista!A6 -> oe | B28: =Registo_Diario_Motorista!B6 -> 46176 | C28: Ida | D28: =Registo_Diario_Motorista!E6 -> maravedis | E28: =Registo_Diario_Motorista!F6 -> 346678 | F28: =Registo_Diario_Motorista!G6 -> 346696 | G28: =IFERROR(__xludf.DUMMYFUNCTION("IFERROR(FILTER(Registo_Diario_Motorista!H:H, Registo_Diario_Motorista!A:A = A28, Registo_Diario_Motorista!C:C = C28, Registo_Diario_Motorista!E:E = D28), 0)"),18.0) -> 18 | H28: SPortagem | I28: =IFERROR(VLOOKUP(H28, Tabela_ConsPort!D:E, 2, FALSE), 0) -> 0 | J28: =SUMIFS(Registo_Diario_Motorista!N:N, Registo_Diario_Motorista!A:A, A28, Registo_Diario_Motorista!C:C, C28, Registo_Diario_Motorista!E:E, D28) -> 0 | K28: CAMIAO | L28: =SUMIFS(Registo_Diario_Motorista!J:J, Registo_Diario_Motorista!A:A, A28, Registo_Diario_Motorista!C:C, C28, Registo_Diario_Motorista!E:E, D28) -> 300 | M28: =IF(K28="LEVE","Volume",L28/IF(K28="CAMIAO+REBOQUE",24000,14000)) -> 0.021428571 | N28: =L28*G28 -> 5400 | O28: =SUMIF(A:A,A28,N:N) -> 175976 | P28: =IF(OR(L28=0, I28="VAZIO", I28="RETORNO"), 1, If(I28="CAMIAO", IF(L28/14000 >= 1, 1, L28/14000), IF(L28/24000 >= 1, 1, L28/24000))) -> 0.0125 | Q28: =VLOOKUP(L28, Tabela_ConsPort!$A$2:$B$7, 2, TRUE) -> 25 | R28: =Q28/100*G28 -> 4.5 | S28: 1.83 | T28: =R28*S28 -> 8.235 | U28: =(G28*2.5)/100 -> 0.45 | V28: =U28*0.3 -> 0.135 | W28: =custo_motorista_e_veiculo!C$11*G28 -> 4.8083589 | X28: =G28*custo_motorista_e_veiculo!L$13 -> 4.9431263 | Y28: =SUMIFS(Registo_Diario_Motorista!O:O, Registo_Diario_Motorista!A:A, A28, Registo_Diario_Motorista!C:C, C28, Registo_Diario_Motorista!E:E, D28) -> 0 | Z28: =SUMIFS(Registo_Diario_Motorista!P:P, Registo_Diario_Motorista!A:A, A28, Registo_Diario_Motorista!C:C, C28, Registo_Diario_Motorista!E:E, D28) -> 0 | AA28: =SUMIFS(Registo_Diario_Motorista!Q:Q, Registo_Diario_Motorista!A:A, A28, Registo_Diario_Motorista!C:C, C28, Registo_Diario_Motorista!E:E, D28) -> 0 | AB28: =AA28*8 -> 0 | AC28: =J28+T28+W28+X28+V28 -> 18.121485 | AD28: =IFERROR(AC28/L28, 0) -> 0.060404951 | AE28: =P28*SUMIF(A:A,A28,AF:AF) -> 35.223808 | AF28: =SUMIFS(AC:AC,A:A,A28)+SUMIFS(Y:Y,A:A,A28)+SUMIFS(Z:Z,A:A,A28)+SUMIFS(AB:AB,A:A,A28)+SUMIFS(I:I,A:A,A28) -> 313.10051 | AG28: =SUMIFS(AC:AC, A:A, A28) * 1.25 -> 363.68814 | AH28: =SUMIFS(AJ:AJ,A:A,A28) -> 400 | AI28: =SUMIF(A:A, A28, AH:AH) - SUMIF(A:A, A28, AF:AF) -> 782.09538 | AK28: =IF(AI28<0, "🔴 PREJUÍZO", "🟢 OK") -> 🟢 OK | AL28: =IFERROR(__xludf.DUMMYFUNCTION("IFERROR(FILTER(Registo_Diario_Motorista!K:K, Registo_Diario_Motorista!A:A = A28, Registo_Diario_Motorista!C:C = C28), 0)"),"#REF!") -> #REF! | AM28: =IFERROR(__xludf.DUMMYFUNCTION("IFERROR(FILTER(Registo_Diario_Motorista!L:L, Registo_Diario_Motorista!A:A = A28, Registo_Diario_Motorista!C:C = C28), 0)"),"#REF!") -> #REF!
A29: =Registo_Diario_Motorista!A7 -> oe | B29: =Registo_Diario_Motorista!B7 -> 46176 | C29: Ida | D29: =Registo_Diario_Motorista!E7 -> cyr | E29: =Registo_Diario_Motorista!F7 -> 346696 | F29: =Registo_Diario_Motorista!G7 -> 346705 | G29: =IFERROR(__xludf.DUMMYFUNCTION("IFERROR(FILTER(Registo_Diario_Motorista!H:H, Registo_Diario_Motorista!A:A = A29, Registo_Diario_Motorista!C:C = C29, Registo_Diario_Motorista!E:E = D29), 0)"),9.0) -> 9 | H29: SPortagem | I29: =IFERROR(VLOOKUP(H29, Tabela_ConsPort!D:E, 2, FALSE), 0) -> 0 | J29: =SUMIFS(Registo_Diario_Motorista!N:N, Registo_Diario_Motorista!A:A, A29, Registo_Diario_Motorista!C:C, C29, Registo_Diario_Motorista!E:E, D29) -> 0 | K29: CAMIAO | L29: =SUMIFS(Registo_Diario_Motorista!J:J, Registo_Diario_Motorista!A:A, A29, Registo_Diario_Motorista!C:C, C29, Registo_Diario_Motorista!E:E, D29) -> 2312 | M29: =IF(K29="LEVE","Volume",L29/IF(K29="CAMIAO+REBOQUE",24000,14000)) -> 0.16514286 | N29: =L29*G29 -> 20808 | O29: =SUMIF(A:A,A29,N:N) -> 175976 | P29: =IF(OR(L29=0, I29="VAZIO", I29="RETORNO"), 1, If(I29="CAMIAO", IF(L29/14000 >= 1, 1, L29/14000), IF(L29/24000 >= 1, 1, L29/24000))) -> 0.096333333 | Q29: =VLOOKUP(L29, Tabela_ConsPort!$A$2:$B$7, 2, TRUE) -> 25 | R29: =Q29/100*G29 -> 2.25 | S29: 1.83 | T29: =R29*S29 -> 4.1175 | U29: =(G29*2.5)/100 -> 0.225 | V29: =U29*0.3 -> 0.0675 | W29: =custo_motorista_e_veiculo!C$11*G29 -> 2.4041795 | X29: =G29*custo_motorista_e_veiculo!L$13 -> 2.4715632 | Y29: =SUMIFS(Registo_Diario_Motorista!O:O, Registo_Diario_Motorista!A:A, A29, Registo_Diario_Motorista!C:C, C29, Registo_Diario_Motorista!E:E, D29) -> 0 | Z29: =SUMIFS(Registo_Diario_Motorista!P:P, Registo_Diario_Motorista!A:A, A29, Registo_Diario_Motorista!C:C, C29, Registo_Diario_Motorista!E:E, D29) -> 0 | AA29: =SUMIFS(Registo_Diario_Motorista!Q:Q, Registo_Diario_Motorista!A:A, A29, Registo_Diario_Motorista!C:C, C29, Registo_Diario_Motorista!E:E, D29) -> 0 | AB29: =AA29*8 -> 0 | AC29: =J29+T29+W29+X29+V29 -> 9.0607426 | AD29: =IFERROR(AC29/L29, 0) -> 0.0039190063 | AE29: =P29*SUMIF(A:A,A29,AF:AF) -> 271.45815 | AF29: =SUMIFS(AC:AC,A:A,A29)+SUMIFS(Y:Y,A:A,A29)+SUMIFS(Z:Z,A:A,A29)+SUMIFS(AB:AB,A:A,A29)+SUMIFS(I:I,A:A,A29) -> 313.10051 | AG29: =SUMIFS(AC:AC, A:A, A29) * 1.25 -> 363.68814 | AH29: =SUMIFS(AJ:AJ,A:A,A29) -> 400 | AI29: =SUMIF(A:A, A29, AH:AH) - SUMIF(A:A, A29, AF:AF) -> 782.09538 | AK29: =IF(AI29<0, "🔴 PREJUÍZO", "🟢 OK") -> 🟢 OK | AL29: =IFERROR(__xludf.DUMMYFUNCTION("IFERROR(FILTER(Registo_Diario_Motorista!K:K, Registo_Diario_Motorista!A:A = A29, Registo_Diario_Motorista!C:C = C29), 0)"),"#REF!") -> #REF! | AM29: =IFERROR(__xludf.DUMMYFUNCTION("IFERROR(FILTER(Registo_Diario_Motorista!L:L, Registo_Diario_Motorista!A:A = A29, Registo_Diario_Motorista!C:C = C29), 0)"),"#REF!") -> #REF!
A30: =Registo_Diario_Motorista!A8 -> oe | B30: =Registo_Diario_Motorista!B8 -> 46176 | C30: Ida | D30: =Registo_Diario_Motorista!E8 -> vecotorres | E30: =Registo_Diario_Motorista!F8 -> 346705 | F30: =Registo_Diario_Motorista!G8 -> 346716 | G30: =IFERROR(__xludf.DUMMYFUNCTION("IFERROR(FILTER(Registo_Diario_Motorista!H:H, Registo_Diario_Motorista!A:A = A30, Registo_Diario_Motorista!C:C = C30, Registo_Diario_Motorista!E:E = D30), 0)"),11.0) -> 11 | H30: SPortagem | I30: =IFERROR(VLOOKUP(H30, Tabela_ConsPort!D:E, 2, FALSE), 0) -> 0 | J30: =SUMIFS(Registo_Diario_Motorista!N:N, Registo_Diario_Motorista!A:A, A30, Registo_Diario_Motorista!C:C, C30, Registo_Diario_Motorista!E:E, D30) -> 0 | K30: CAMIAO | L30: =SUMIFS(Registo_Diario_Motorista!J:J, Registo_Diario_Motorista!A:A, A30, Registo_Diario_Motorista!C:C, C30, Registo_Diario_Motorista!E:E, D30) -> 4832 | M30: =IF(K30="LEVE","Volume",L30/IF(K30="CAMIAO+REBOQUE",24000,14000)) -> 0.34514286 | N30: =L30*G30 -> 53152 | O30: =SUMIF(A:A,A30,N:N) -> 175976 | P30: =IF(OR(L30=0, I30="VAZIO", I30="RETORNO"), 1, If(I30="CAMIAO", IF(L30/14000 >= 1, 1, L30/14000), IF(L30/24000 >= 1, 1, L30/24000))) -> 0.20133333 | Q30: =VLOOKUP(L30, Tabela_ConsPort!$A$2:$B$7, 2, TRUE) -> 25 | R30: =Q30/100*G30 -> 2.75 | S30: 1.83 | T30: =R30*S30 -> 5.0325 | U30: =(G30*2.5)/100 -> 0.275 | V30: =U30*0.3 -> 0.0825 | W30: =custo_motorista_e_veiculo!C$11*G30 -> 2.9384416 | X30: =G30*custo_motorista_e_veiculo!L$13 -> 3.0207994 | Y30: =SUMIFS(Registo_Diario_Motorista!O:O, Registo_Diario_Motorista!A:A, A30, Registo_Diario_Motorista!C:C, C30, Registo_Diario_Motorista!E:E, D30) -> 0 | Z30: =SUMIFS(Registo_Diario_Motorista!P:P, Registo_Diario_Motorista!A:A, A30, Registo_Diario_Motorista!C:C, C30, Registo_Diario_Motorista!E:E, D30) -> 0 | AA30: =SUMIFS(Registo_Diario_Motorista!Q:Q, Registo_Diario_Motorista!A:A, A30, Registo_Diario_Motorista!C:C, C30, Registo_Diario_Motorista!E:E, D30) -> 0 | AB30: =AA30*8 -> 0 | AC30: =J30+T30+W30+X30+V30 -> 11.074241 | AD30: =IFERROR(AC30/L30, 0) -> 0.0022918545 | AE30: =P30*SUMIF(A:A,A30,AF:AF) -> 567.33813 | AF30: =SUMIFS(AC:AC,A:A,A30)+SUMIFS(Y:Y,A:A,A30)+SUMIFS(Z:Z,A:A,A30)+SUMIFS(AB:AB,A:A,A30)+SUMIFS(I:I,A:A,A30) -> 313.10051 | AG30: =SUMIFS(AC:AC, A:A, A30) * 1.25 -> 363.68814 | AH30: =SUMIFS(AJ:AJ,A:A,A30) -> 400 | AI30: =SUMIF(A:A, A30, AH:AH) - SUMIF(A:A, A30, AF:AF) -> 782.09538 | AK30: =IF(AI30<0, "🔴 PREJUÍZO", "🟢 OK") -> 🟢 OK | AL30: =IFERROR(__xludf.DUMMYFUNCTION("IFERROR(FILTER(Registo_Diario_Motorista!K:K, Registo_Diario_Motorista!A:A = A30, Registo_Diario_Motorista!C:C = C30), 0)"),"#REF!") -> #REF! | AM30: =IFERROR(__xludf.DUMMYFUNCTION("IFERROR(FILTER(Registo_Diario_Motorista!L:L, Registo_Diario_Motorista!A:A = A30, Registo_Diario_Motorista!C:C = C30), 0)"),"#REF!") -> #REF!
A31: =Registo_Diario_Motorista!A9 -> oe | B31: =Registo_Diario_Motorista!B9 -> 46176 | C31: Ida | D31: =Registo_Diario_Motorista!E9 -> liscampo | E31: =Registo_Diario_Motorista!F9 -> 346716 | F31: =Registo_Diario_Motorista!G9 -> 346750 | G31: =IFERROR(__xludf.DUMMYFUNCTION("IFERROR(FILTER(Registo_Diario_Motorista!H:H, Registo_Diario_Motorista!A:A = A31, Registo_Diario_Motorista!C:C = C31, Registo_Diario_Motorista!E:E = D31), 0)"),34.0) -> 34 | H31: SPortagem | I31: =IFERROR(VLOOKUP(H31, Tabela_ConsPort!D:E, 2, FALSE), 0) -> 0 | J31: =SUMIFS(Registo_Diario_Motorista!N:N, Registo_Diario_Motorista!A:A, A31, Registo_Diario_Motorista!C:C, C31, Registo_Diario_Motorista!E:E, D31) -> 0 | K31: CAMIAO | L31: =SUMIFS(Registo_Diario_Motorista!J:J, Registo_Diario_Motorista!A:A, A31, Registo_Diario_Motorista!C:C, C31, Registo_Diario_Motorista!E:E, D31) -> 800 | M31: =IF(K31="LEVE","Volume",L31/IF(K31="CAMIAO+REBOQUE",24000,14000)) -> 0.057142857 | N31: =L31*G31 -> 27200 | O31: =SUMIF(A:A,A31,N:N) -> 175976 | P31: =IF(OR(L31=0, I31="VAZIO", I31="RETORNO"), 1, If(I31="CAMIAO", IF(L31/14000 >= 1, 1, L31/14000), IF(L31/24000 >= 1, 1, L31/24000))) -> 0.033333333 | Q31: =VLOOKUP(L31, Tabela_ConsPort!$A$2:$B$7, 2, TRUE) -> 25 | R31: =Q31/100*G31 -> 8.5 | S31: 1.83 | T31: =R31*S31 -> 15.555 | U31: =(G31*2.5)/100 -> 0.85 | V31: =U31*0.3 -> 0.255 | W31: =custo_motorista_e_veiculo!C$11*G31 -> 9.0824558 | X31: =G31*custo_motorista_e_veiculo!L$13 -> 9.3370164 | Y31: =SUMIFS(Registo_Diario_Motorista!O:O, Registo_Diario_Motorista!A:A, A31, Registo_Diario_Motorista!C:C, C31, Registo_Diario_Motorista!E:E, D31) -> 0 | Z31: =SUMIFS(Registo_Diario_Motorista!P:P, Registo_Diario_Motorista!A:A, A31, Registo_Diario_Motorista!C:C, C31, Registo_Diario_Motorista!E:E, D31) -> 0 | AA31: =SUMIFS(Registo_Diario_Motorista!Q:Q, Registo_Diario_Motorista!A:A, A31, Registo_Diario_Motorista!C:C, C31, Registo_Diario_Motorista!E:E, D31) -> 0 | AB31: =AA31*8 -> 0 | AC31: =J31+T31+W31+X31+V31 -> 34.229472 | AD31: =IFERROR(AC31/L31, 0) -> 0.04278684 | AE31: =P31*SUMIF(A:A,A31,AF:AF) -> 93.930154 | AF31: =SUMIFS(AC:AC,A:A,A31)+SUMIFS(Y:Y,A:A,A31)+SUMIFS(Z:Z,A:A,A31)+SUMIFS(AB:AB,A:A,A31)+SUMIFS(I:I,A:A,A31) -> 313.10051 | AG31: =SUMIFS(AC:AC, A:A, A31) * 1.25 -> 363.68814 | AH31: =SUMIFS(AJ:AJ,A:A,A31) -> 400 | AI31: =SUMIF(A:A, A31, AH:AH) - SUMIF(A:A, A31, AF:AF) -> 782.09538 | AK31: =IF(AI31<0, "🔴 PREJUÍZO", "🟢 OK") -> 🟢 OK | AL31: =IFERROR(__xludf.DUMMYFUNCTION("IFERROR(FILTER(Registo_Diario_Motorista!K:K, Registo_Diario_Motorista!A:A = A31, Registo_Diario_Motorista!C:C = C31), 0)"),"#REF!") -> #REF! | AM31: =IFERROR(__xludf.DUMMYFUNCTION("IFERROR(FILTER(Registo_Diario_Motorista!L:L, Registo_Diario_Motorista!A:A = A31, Registo_Diario_Motorista!C:C = C31), 0)"),"#REF!") -> #REF!
A32: =Registo_Diario_Motorista!A10 -> oe | B32: =Registo_Diario_Motorista!B10 -> 46176 | C32: Ida | D32: =Registo_Diario_Motorista!E10 -> morgado | E32: =Registo_Diario_Motorista!F10 -> 346750 | F32: =Registo_Diario_Motorista!G10 -> 346812 | G32: =IFERROR(__xludf.DUMMYFUNCTION("IFERROR(FILTER(Registo_Diario_Motorista!H:H, Registo_Diario_Motorista!A:A = A32, Registo_Diario_Motorista!C:C = C32, Registo_Diario_Motorista!E:E = D32), 0)"),62.0) -> 62 | H32: SPortagem | I32: =IFERROR(VLOOKUP(H32, Tabela_ConsPort!D:E, 2, FALSE), 0) -> 0 | J32: =SUMIFS(Registo_Diario_Motorista!N:N, Registo_Diario_Motorista!A:A, A32, Registo_Diario_Motorista!C:C, C32, Registo_Diario_Motorista!E:E, D32) -> 0 | K32: CAMIAO | L32: =SUMIFS(Registo_Diario_Motorista!J:J, Registo_Diario_Motorista!A:A, A32, Registo_Diario_Motorista!C:C, C32, Registo_Diario_Motorista!E:E, D32) -> 419 | M32: =IF(K32="LEVE","Volume",L32/IF(K32="CAMIAO+REBOQUE",24000,14000)) -> 0.029928571 | N32: =L32*G32 -> 25978 | O32: =SUMIF(A:A,A32,N:N) -> 175976 | P32: =IF(OR(L32=0, I32="VAZIO", I32="RETORNO"), 1, If(I32="CAMIAO", IF(L32/14000 >= 1, 1, L32/14000), IF(L32/24000 >= 1, 1, L32/24000))) -> 0.017458333 | Q32: =VLOOKUP(L32, Tabela_ConsPort!$A$2:$B$7, 2, TRUE) -> 25 | R32: =Q32/100*G32 -> 15.5 | S32: 1.83 | T32: =R32*S32 -> 28.365 | U32: =(G32*2.5)/100 -> 1.55 | V32: =U32*0.3 -> 0.465 | W32: =custo_motorista_e_veiculo!C$11*G32 -> 16.562125 | X32: =G32*custo_motorista_e_veiculo!L$13 -> 17.026324 | Y32: =SUMIFS(Registo_Diario_Motorista!O:O, Registo_Diario_Motorista!A:A, A32, Registo_Diario_Motorista!C:C, C32, Registo_Diario_Motorista!E:E, D32) -> 0 | Z32: =SUMIFS(Registo_Diario_Motorista!P:P, Registo_Diario_Motorista!A:A, A32, Registo_Diario_Motorista!C:C, C32, Registo_Diario_Motorista!E:E, D32) -> 0 | AA32: =SUMIFS(Registo_Diario_Motorista!Q:Q, Registo_Diario_Motorista!A:A, A32, Registo_Diario_Motorista!C:C, C32, Registo_Diario_Motorista!E:E, D32) -> 0 | AB32: =AA32*8 -> 0 | AC32: =J32+T32+W32+X32+V32 -> 62.418449 | AD32: =IFERROR(AC32/L32, 0) -> 0.14897005 | AE32: =P32*SUMIF(A:A,A32,AF:AF) -> 49.195918 | AF32: =SUMIFS(AC:AC,A:A,A32)+SUMIFS(Y:Y,A:A,A32)+SUMIFS(Z:Z,A:A,A32)+SUMIFS(AB:AB,A:A,A32)+SUMIFS(I:I,A:A,A32) -> 313.10051 | AG32: =SUMIFS(AC:AC, A:A, A32) * 1.25 -> 363.68814 | AH32: =SUMIFS(AJ:AJ,A:A,A32) -> 400 | AI32: =SUMIF(A:A, A32, AH:AH) - SUMIF(A:A, A32, AF:AF) -> 782.09538 | AK32: =IF(AI32<0, "🔴 PREJUÍZO", "🟢 OK") -> 🟢 OK | AL32: =IFERROR(__xludf.DUMMYFUNCTION("IFERROR(FILTER(Registo_Diario_Motorista!K:K, Registo_Diario_Motorista!A:A = A32, Registo_Diario_Motorista!C:C = C32), 0)"),"#REF!") -> #REF! | AM32: =IFERROR(__xludf.DUMMYFUNCTION("IFERROR(FILTER(Registo_Diario_Motorista!L:L, Registo_Diario_Motorista!A:A = A32, Registo_Diario_Motorista!C:C = C32), 0)"),"#REF!") -> #REF!
A33: =Registo_Diario_Motorista!A11 -> oe | B33: =Registo_Diario_Motorista!B11 -> 46176 | C33: Ida | D33: =Registo_Diario_Motorista!E11 -> esequiel | E33: =Registo_Diario_Motorista!F11 -> 346812 | F33: =Registo_Diario_Motorista!G11 -> 346820 | G33: =IFERROR(__xludf.DUMMYFUNCTION("IFERROR(FILTER(Registo_Diario_Motorista!H:H, Registo_Diario_Motorista!A:A = A33, Registo_Diario_Motorista!C:C = C33, Registo_Diario_Motorista!E:E = D33), 0)"),8.0) -> 8 | H33: SPortagem | I33: =IFERROR(VLOOKUP(H33, Tabela_ConsPort!D:E, 2, FALSE), 0) -> 0 | J33: =SUMIFS(Registo_Diario_Motorista!N:N, Registo_Diario_Motorista!A:A, A33, Registo_Diario_Motorista!C:C, C33, Registo_Diario_Motorista!E:E, D33) -> 0 | K33: CAMIAO | L33: =SUMIFS(Registo_Diario_Motorista!J:J, Registo_Diario_Motorista!A:A, A33, Registo_Diario_Motorista!C:C, C33, Registo_Diario_Motorista!E:E, D33) -> 500 | M33: =IF(K33="LEVE","Volume",L33/IF(K33="CAMIAO+REBOQUE",24000,14000)) -> 0.035714286 | N33: =L33*G33 -> 4000 | O33: =SUMIF(A:A,A33,N:N) -> 175976 | P33: =IF(OR(L33=0, I33="VAZIO", I33="RETORNO"), 1, If(I33="CAMIAO", IF(L33/14000 >= 1, 1, L33/14000), IF(L33/24000 >= 1, 1, L33/24000))) -> 0.020833333 | Q33: =VLOOKUP(L33, Tabela_ConsPort!$A$2:$B$7, 2, TRUE) -> 25 | R33: =Q33/100*G33 -> 2 | S33: 1.83 | T33: =R33*S33 -> 3.66 | U33: =(G33*2.5)/100 -> 0.2 | V33: =U33*0.3 -> 0.06 | W33: =custo_motorista_e_veiculo!C$11*G33 -> 2.1370484 | X33: =G33*custo_motorista_e_veiculo!L$13 -> 2.196945 | Y33: =SUMIFS(Registo_Diario_Motorista!O:O, Registo_Diario_Motorista!A:A, A33, Registo_Diario_Motorista!C:C, C33, Registo_Diario_Motorista!E:E, D33) -> 0 | Z33: =SUMIFS(Registo_Diario_Motorista!P:P, Registo_Diario_Motorista!A:A, A33, Registo_Diario_Motorista!C:C, C33, Registo_Diario_Motorista!E:E, D33) -> 0 | AA33: =SUMIFS(Registo_Diario_Motorista!Q:Q, Registo_Diario_Motorista!A:A, A33, Registo_Diario_Motorista!C:C, C33, Registo_Diario_Motorista!E:E, D33) -> 0 | AB33: =AA33*8 -> 0 | AC33: =J33+T33+W33+X33+V33 -> 8.0539935 | AD33: =IFERROR(AC33/L33, 0) -> 0.016107987 | AE33: =P33*SUMIF(A:A,A33,AF:AF) -> 58.706346 | AF33: =SUMIFS(AC:AC,A:A,A33)+SUMIFS(Y:Y,A:A,A33)+SUMIFS(Z:Z,A:A,A33)+SUMIFS(AB:AB,A:A,A33)+SUMIFS(I:I,A:A,A33) -> 313.10051 | AG33: =SUMIFS(AC:AC, A:A, A33) * 1.25 -> 363.68814 | AH33: =SUMIFS(AJ:AJ,A:A,A33) -> 400 | AI33: =SUMIF(A:A, A33, AH:AH) - SUMIF(A:A, A33, AF:AF) -> 782.09538 | AK33: =IF(AI33<0, "🔴 PREJUÍZO", "🟢 OK") -> 🟢 OK | AL33: =IFERROR(__xludf.DUMMYFUNCTION("IFERROR(FILTER(Registo_Diario_Motorista!K:K, Registo_Diario_Motorista!A:A = A33, Registo_Diario_Motorista!C:C = C33), 0)"),"#REF!") -> #REF! | AM33: =IFERROR(__xludf.DUMMYFUNCTION("IFERROR(FILTER(Registo_Diario_Motorista!L:L, Registo_Diario_Motorista!A:A = A33, Registo_Diario_Motorista!C:C = C33), 0)"),"#REF!") -> #REF!
A34: =Registo_Diario_Motorista!A12 -> oe | B34: =Registo_Diario_Motorista!B12 -> 46176 | C34: Volta | D34: =Registo_Diario_Motorista!E12 -> volta | E34: =Registo_Diario_Motorista!F12 -> 346820 | F34: =Registo_Diario_Motorista!G12 -> 346873 | G34: =IFERROR(__xludf.DUMMYFUNCTION("IFERROR(FILTER(Registo_Diario_Motorista!H:H, Registo_Diario_Motorista!A:A = A34, Registo_Diario_Motorista!C:C = C34, Registo_Diario_Motorista!E:E = D34), 0)"),53.0) -> 53 | H34: SPortagem | I34: =IFERROR(VLOOKUP(H34, Tabela_ConsPort!D:E, 2, FALSE), 0) -> 0 | J34: =SUMIFS(Registo_Diario_Motorista!N:N, Registo_Diario_Motorista!A:A, A34, Registo_Diario_Motorista!C:C, C34, Registo_Diario_Motorista!E:E, D34) -> 0 | K34: =IFERROR(__xludf.DUMMYFUNCTION("IFERROR(FILTER(Registo_Diario_Motorista!D:D, Registo_Diario_Motorista!A:A = A34, Registo_Diario_Motorista!C:C = C34), """")"),"VAZIO") -> VAZIO | L34: =SUMIFS(Registo_Diario_Motorista!J:J, Registo_Diario_Motorista!A:A, A34, Registo_Diario_Motorista!C:C, C34, Registo_Diario_Motorista!E:E, D34) -> 0 | M34: =IF(K34="LEVE","Volume",L34/IF(K34="CAMIAO+REBOQUE",24000,14000)) -> 0 | N34: =L34*G34 -> 0 | O34: =SUMIF(A:A,A34,N:N) -> 175976 | P34: =IF(OR(L34=0, I34="VAZIO", I34="RETORNO"), 1, If(I34="CAMIAO", IF(L34/14000 >= 1, 1, L34/14000), IF(L34/24000 >= 1, 1, L34/24000))) -> 1 | Q34: =VLOOKUP(L34, Tabela_ConsPort!$A$2:$B$7, 2, TRUE) -> 25 | R34: =Q34/100*G34 -> 13.25 | S34: 1.83 | T34: =R34*S34 -> 24.2475 | U34: =(G34*2.5)/100 -> 1.325 | V34: =U34*0.3 -> 0.3975 | W34: =custo_motorista_e_veiculo!C$11*G34 -> 14.157946 | X34: =G34*custo_motorista_e_veiculo!L$13 -> 14.554761 | Y34: =SUMIFS(Registo_Diario_Motorista!O:O, Registo_Diario_Motorista!A:A, A34, Registo_Diario_Motorista!C:C, C34, Registo_Diario_Motorista!E:E, D34) -> 0 | Z34: =SUMIFS(Registo_Diario_Motorista!P:P, Registo_Diario_Motorista!A:A, A34, Registo_Diario_Motorista!C:C, C34, Registo_Diario_Motorista!E:E, D34) -> 0 | AA34: =SUMIFS(Registo_Diario_Motorista!Q:Q, Registo_Diario_Motorista!A:A, A34, Registo_Diario_Motorista!C:C, C34, Registo_Diario_Motorista!E:E, D34) -> 1 | AB34: =AA34*8 -> 8 | AC34: =J34+T34+W34+X34+V34 -> 53.357707 | AD34: =IFERROR(AC34/L34, 0) -> 0 | AE34: =P34*SUMIF(A:A,A34,AF:AF) -> 2817.9046 | AF34: =SUMIFS(AC:AC,A:A,A34)+SUMIFS(Y:Y,A:A,A34)+SUMIFS(Z:Z,A:A,A34)+SUMIFS(AB:AB,A:A,A34)+SUMIFS(I:I,A:A,A34) -> 313.10051 | AG34: =SUMIFS(AC:AC, A:A, A34) * 1.25 -> 363.68814 | AH34: =SUMIFS(AJ:AJ,A:A,A34) -> 400 | AI34: =SUMIF(A:A, A34, AH:AH) - SUMIF(A:A, A34, AF:AF) -> 782.09538 | AK34: =IF(AI34<0, "🔴 PREJUÍZO", "🟢 OK") -> 🟢 OK | AL34: =IFERROR(__xludf.DUMMYFUNCTION("IFERROR(FILTER(Registo_Diario_Motorista!K:K, Registo_Diario_Motorista!A:A = A34, Registo_Diario_Motorista!C:C = C34), 0)"),"") | AM34: =IFERROR(__xludf.DUMMYFUNCTION("IFERROR(FILTER(Registo_Diario_Motorista!L:L, Registo_Diario_Motorista!A:A = A34, Registo_Diario_Motorista!C:C = C34), 0)"),"")
A35: =Registo_Diario_Motorista!A13 | B35: =Registo_Diario_Motorista!B13 | C35: Volta | E35: =Registo_Diario_Motorista!F14 | F35: =Registo_Diario_Motorista!G14 | G35: =IFERROR(__xludf.DUMMYFUNCTION("IFERROR(FILTER(Registo_Diario_Motorista!H:H, Registo_Diario_Motorista!A:A = A35, Registo_Diario_Motorista!C:C = C35), 0)"),0.0) -> 0 | H35: =IFERROR(VLOOKUP(A35, Registo_Diario_Motorista!$A$2:$M$5001, 13, FALSE), "") | I35: =IFERROR(VLOOKUP(H35, Tabela_ConsPort!D:E, 2, FALSE), 0) -> 0 | J35: =IFERROR(__xludf.DUMMYFUNCTION("IFERROR(FILTER(Registo_Diario_Motorista!N:N, Registo_Diario_Motorista!A:A = A35, Registo_Diario_Motorista!C:C = C35), 0)"),0.0) -> 0 | K35: =IFERROR(__xludf.DUMMYFUNCTION("IFERROR(FILTER(Registo_Diario_Motorista!D:D, Registo_Diario_Motorista!A:A = A35, Registo_Diario_Motorista!C:C = C35), """")"),"") | L35: =SUMIFS(Registo_Diario_Motorista!J:J, Registo_Diario_Motorista!A:A, A35, Registo_Diario_Motorista!C:C, C35, Registo_Diario_Motorista!E:E, D35) -> 0 | M35: =IF(K35="LEVE","Volume",L35/IF(K35="CAMIAO+REBOQUE",24000,14000)) -> 0 | N35: =L35*G35 -> 0 | O35: =SUMIF(A:A,A35,N:N) -> 0 | P35: =IF(OR(L35=0, I35="VAZIO", I35="RETORNO"), 1, If(I35="CAMIAO", IF(L35/14000 >= 1, 1, L35/14000), IF(L35/24000 >= 1, 1, L35/24000))) -> 1 | Q35: =VLOOKUP(L35, Tabela_ConsPort!$A$2:$B$7, 2, TRUE) -> 25 | R35: =Q35/100*G35 -> 0 | S35: 1.83 | T35: =R35*S35 -> 0 | U35: =(G35*2.5)/100 -> 0 | V35: =U35*0.3 -> 0 | W35: =custo_motorista_e_veiculo!C$11*G35 -> 0 | X35: =G35*custo_motorista_e_veiculo!L$13 -> 0 | Y35: =SUMIFS(Registo_Diario_Motorista!O:O, Registo_Diario_Motorista!A:A, A35, Registo_Diario_Motorista!C:C, C35, Registo_Diario_Motorista!E:E, D35) -> 0 | Z35: =SUMIFS(Registo_Diario_Motorista!P:P, Registo_Diario_Motorista!A:A, A35, Registo_Diario_Motorista!C:C, C35, Registo_Diario_Motorista!E:E, D35) -> 0 | AA35: =SUMIFS(Registo_Diario_Motorista!Q:Q, Registo_Diario_Motorista!A:A, A35, Registo_Diario_Motorista!C:C, C35, Registo_Diario_Motorista!E:E, D35) -> 0 | AB35: =AA35*8 -> 0 | AC35: =J35+T35+W35+X35+V35 -> 0 | AD35: =IFERROR(AC35/L35, 0) -> 0 | AE35: =P35*SUMIF(A:A,A35,AF:AF) -> 0 | AF35: =SUMIFS(AC:AC,A:A,A35)+SUMIFS(Y:Y,A:A,A35)+SUMIFS(Z:Z,A:A,A35)+SUMIFS(AB:AB,A:A,A35)+SUMIFS(I:I,A:A,A35) -> 0 | AG35: =SUMIFS(AC:AC, A:A, A35) * 1.25 -> 0 | AH35: =SUMIFS(AJ:AJ,A:A,A35) -> 0 | AI35: =SUMIF(A:A, A35, AH:AH) - SUMIF(A:A, A35, AF:AF) -> 0 | AK35: =IF(AI35<0, "🔴 PREJUÍZO", "🟢 OK") -> 🟢 OK | AL35: =IFERROR(__xludf.DUMMYFUNCTION("IFERROR(FILTER(Registo_Diario_Motorista!K:K, Registo_Diario_Motorista!A:A = A35, Registo_Diario_Motorista!C:C = C35), 0)"),0.0) -> 0 | AM35: =IFERROR(__xludf.DUMMYFUNCTION("IFERROR(FILTER(Registo_Diario_Motorista!L:L, Registo_Diario_Motorista!A:A = A35, Registo_Diario_Motorista!C:C = C35), 0)"),0.0) -> 0
